Workbook
Name const_start: Inputs!$D$25
Name Constr_Finish_Date: Inputs!$E$27
Name Constr_Finish_Mo: Inputs!$D$27
Name Construction_Start_Date: Inputs!$E$25
Name Diligence_Begin_Date: Inputs!$E$20
Name Greenlight_Date: Inputs!$E$21
Name Greenlight_Mo: Inputs!$D$21
Name Land_Closing_Mo: Inputs!$D$22
Name lease_up_period: Inputs!$E$31
Name logistics_cost: '(Z+) Monthly CF'!$D$65
Name mod_costs: '(Z+) Monthly CF'!$D$64
Name perm_fees: '(Z+) Financing'!$H$22
Name perm_proceeds: '(Z+) Financing'!$H$19
Name refinance_date: Inputs!$E$34
Name sale_month: Inputs!$E$38

Sheet Inputs
C3: Inputs
C5: Location | F5: Budget Summary | G5: Budget | H5: $/Unit | J5: Underwriting Assumptions | N5: Massing Information
C6: Address | D6: 2828 STANFORD AVE | F6: Acquisition Costs | G6: =IFERROR('(Z+) Dev Budget'!G10,0) -> 1601600 | H6: =IFERROR(G6/$H$14,0) -> 7150 | J6: Vacancy & Credit Loss | L6: 0.03 | N6: Number of Buildings | O6: 1
C7: City | D7: Los Angeles | F7: Hard Costs | G7: =IFERROR('(Z+) Dev Budget'!G30,0) -> 44063340 | H7: =IFERROR(G7/$H$14,0) -> 196711.34 | J7: Rent Growth | L7: =Dashboard!W21 -> 0.025 | N7: Podium SF | O7: 14289
C8: State | D8: California | F8: Soft Costs | G8: ='(Z+) Dev Budget'!G109 -> 3635373 | H8: =+IFERROR(G8/$H$14,0) -> 16229.344 | J8: OpEx Ratio | L8: ='(Z+) OpEx'!D27 -> 0.31681548 | N8: Podium Levels | O8: 1
C9: Zip Code | D9: 90011-2018 | F9: Admin Costs | G9: ='(Z+) Dev Budget'!G115 -> 2608935.6 | H9: =+IFERROR(G9/$H$14,0) -> 11647.034 | J9: Construction Cost Escalation | L9: 0.04 | N9: # of Parking Stalls - Surface | O9: 38
F10: Financing Costs | G10: ='(Z+) Dev Budget'!G124 -> 8268359.9 | H10: =IFERROR(G10/$H$14,0) -> 36912.321 | J10: Rent Trending Begin Mo. | L10: =1 -> 1 | N10: # of Dwelling Units (Total) | O10: =SUM(O11:O13) -> 224
C11: Parcel Info | F11: Total | G11: =SUM(G6:G10) -> 60177608 | H11: =G11/$H$14 -> 268650.04 | J11: Precon Soft Cost Expenditure | L11: =60/100 -> 0.6 | N11: 1-BR 1-BA | O11: 224
C12: Zoning | D12: R3-1 | N12: 2-BR 1-BA | O12: 0
C13: Gross Lot Size (SF) | D13: 29482 | F13: Effective Development Potential | J13: Capital Stack | N13: 3-BR 2-BA | O13: 0
C14: Lot Length (ft) | D14: 216 | F14: Dwelling Units | H14: =O10 -> 224 | J14: Acquisition | N14: Service Modules (Total) | O14: =SUM(O15:O20) -> 17
C15: Lot Width (ft) | D15: 135 | F15: Moduler Units | H15: =(O11*1)+(O12*2)+(O13*2) -> 224 | J15: Equity | K15: =L15/SUM($L$15:$L$16) -> 1 | L15: ='(Z+) Dev Budget'!G118*(1-'(Z+) Financing'!D18) -> 15572775 | N15: Staircase Unit | O15: 17
C16: Gross Building SF | D16: 13582.5 | F16: Parking Stalls | H16: =O9 -> 38 | J16: Debt | K16: =L16/SUM($L$15:$L$16) -> 0 | L16: ='(Z+) Financing'!D10 -> 0 | N16: Bike Parking Units | O16: 0
C17: Net Rentable SF | D17: 101416 | J17: Total Acquisition Capitalization | L17: =+SUM(L15:L16) -> 15572775 | N17: Laundry Rooms | O17: 0
J18: Development | N18: Lobbies | O18: 0
C19: Timing Assumptions | D19: Month | E19: Date | F19: Rent Growth | G19: Exp Growth | J19: Equity | K19: =L19/SUM($L$19,$L$20) -> 0.39618737 | L19: ='(Z+) Dev Budget'!G126-L20 -> 23841608 | N19: Mechanical Rooms | O19: 0
C20: Diligence Begin Date | D20: 1 | E20: 46357 | F20: =+IFERROR(INDEX('(Z+) Monthly CF'!$F$9:$HB$9,1,MATCH(Inputs!$D20,'(Z+) Monthly CF'!$F$5:$HB$5,0)),0) -> 1 | G20: =+IFERROR(INDEX('(Z+) Monthly CF'!$F$10:$HB$10,1,MATCH(Inputs!D20,'(Z+) Monthly CF'!$F$5:$HB$5,0)),0) -> 1 | J20: Senior Debt | K20: =L20/SUM($L$19,$L$20) -> 0.60381263 | L20: ='(Z+) Financing'!D38 -> 36336000 | N20: Other Service Mods | O20: 0
C21: Greenlight Date | D21: 4 | E21: =+IFERROR(EOMONTH(E20,D21-1),0) -> 46477 | F21: =+IFERROR(INDEX('(Z+) Monthly CF'!$F$9:$HB$9,1,MATCH(Inputs!$D21,'(Z+) Monthly CF'!$F$5:$HB$5,0)),0) -> 1.0061922 | G21: =+IFERROR(INDEX('(Z+) Monthly CF'!$F$10:$HB$10,1,MATCH(Inputs!D21,'(Z+) Monthly CF'!$F$5:$HB$5,0)),0) -> 1.0074171 | J21: Total Development Capitalization | L21: =+SUM(L19,L20) -> 60177608 | N21: Total # of Modules | O21: =(O11*1)+(O12*2)+(O13*2)+O14 -> 241
C22: Land Closing Date | D22: =Greenlight_Mo -> 4 | E22: =+IFERROR(EOMONTH(E20,D21-1),0) -> 46477 | F22: =+IFERROR(INDEX('(Z+) Monthly CF'!$F$9:$HB$9,1,MATCH(Inputs!$D22,'(Z+) Monthly CF'!$F$5:$HB$5,0)),0) -> 1.0061922 | G22: =+IFERROR(INDEX('(Z+) Monthly CF'!$F$10:$HB$10,1,MATCH(Inputs!D22,'(Z+) Monthly CF'!$F$5:$HB$5,0)),0) -> 1.0074171 | J22: Stabilization
C23: Preconstruction Period (Months) | E23: 6 | J23: Equity | K23: =(L23/SUM($L$23:$L$24)) -> 0.19206922 | L23: ='(Z+) Dev Budget'!G126-L24-'(Z+) Dev Budget'!G129+'(Z+) Financing'!H22*'(Z+) Financing'!H19 -> 11444788 | N23: Affordability/Set-Aside Detail
C24: RTI Date | D24: =+IFERROR(D21+E23,0) -> 10 | E24: =EOMONTH(E21,E23) -> 46660 | J24: Debt | K24: =(L24/SUM($L$23:$L$24)) -> 0.80793078 | L24: ='(Z+) Financing'!H19 -> 48142000 | N24: Set Aside Options | O24: # of Units
C25: Construction Start | D25: =+D24 -> 10 | E25: =+EOMONTH(E21,E23) -> 46660 | F25: =+INDEX('(Z+) Monthly CF'!$F$9:$HB$9,1,MATCH(Inputs!$D25,'(Z+) Monthly CF'!$F$5:$HB$5,0)) -> 1.018692 | G25: =+INDEX('(Z+) Monthly CF'!$F$10:$HB$10,1,MATCH(Inputs!D25,'(Z+) Monthly CF'!$F$5:$HB$5,0)) -> 1.0224167 | J25: Total Stabilized Capitalization | L25: =+SUM(L23:L24) -> 59586788 | N25: Required ELI Units | O25: 0
C26: Construction Timeline (Months) | E26: =Dashboard!W19 -> 11 | N26: Required VLI Units | O26: 0
C27: Construction Finishing Date | D27: =+IFERROR(E26+D25,0) -> 21 | E27: =EOMONTH(E25,E26) -> 46996 | F27: =+INDEX('(Z+) Monthly CF'!$F$9:$HB$9,1,MATCH(Inputs!$D27,'(Z+) Monthly CF'!$F$5:$HB$5,0)) -> 1.0420129 | G27: =+INDEX('(Z+) Monthly CF'!$F$10:$HB$10,1,MATCH(Inputs!D27,'(Z+) Monthly CF'!$F$5:$HB$5,0)) -> 1.0504983 | J27: Model Z Schedule | K27: Duration (Months) | L27: Date | N27: Required LI Units | O27: =ROUNDUP((H14-1)*0.8,0) -> 179
C28: Total Development Timeline | E28: =SUM(E26,E23) -> 17 | J28: Site Acquisition and Planning | K28: 3 | L28: =Greenlight_Date-27 -> 46450 | N28: Required Mod Units | O28: =H14-1-O27 -> 44
C29: Occupancy Date | D29: =+IFERROR(D27+1,0) -> 22 | E29: =+EOMONTH(E27,1) -> 47026 | F29: =+INDEX('(Z+) Monthly CF'!$F$9:$HB$9,1,MATCH(Inputs!$D29,'(Z+) Monthly CF'!$F$5:$HB$5,0)) -> 1.0441593 | G29: =+INDEX('(Z+) Monthly CF'!$F$10:$HB$10,1,MATCH(Inputs!D29,'(Z+) Monthly CF'!$F$5:$HB$5,0)) -> 1.0530344 | J29: Z/Suite Design | K29: 3 | L29: =+L28 -> 46450 | N29: ED1/100% Affordable? | O29: No
C30: Leased Units/Month | E30: 30 | J30: Permits and Entitlement | K30: 6 | L30: =+EOMONTH(L28,K28-1) -> 46538 | N30: HUD/TCAC AMI | O30: 1
C31: Lease-Up Period | E31: =+ROUNDUP('(Z+) Rent Roll'!E20/E30,0) -> 8 | J31: Site Prep and Preconstruction | K31: 6 | L31: =+EOMONTH(L30,K30) -> 46721 | N31: HCD AMI | O31: 1
C32: Refinancing Period | E32: =3 -> 3 | J32: Modular Manufacturing | K32: 2 | L32: =+EOMONTH(L30,K30+4) -> 46843 | N32: Set Aside Restricted Units (HCD) | O32: =SUM(O25:O28) -> 223
C33: Stabilization Period (Months) | E33: =+E32+E31 -> 11 | J33: Construction | K33: 12 | L33: =+EOMONTH(L31,K31) -> 46904
C34: Stabilization/Refinance Date | D34: =33 -> 33 | E34: =EOMONTH(E29,E33) -> 47361 | F34: =+INDEX('(Z+) Monthly CF'!$F$9:$HB$9,1,MATCH(Inputs!$D34,'(Z+) Monthly CF'!$F$5:$HB$5,0)) -> 1.0680633 | G34: =+INDEX('(Z+) Monthly CF'!$F$10:$HB$10,1,MATCH(Inputs!D34,'(Z+) Monthly CF'!$F$5:$HB$5,0)) -> 1.0813379 | N34: Legend
C35: Time to Stabilization | E35: =ROUND(DAYS360(E21,E34)/30,0) -> 29 | N35: Inputs (Z/Suite) | O35: Light Blue
C36: Total Hold Period (Months) | E36: =IFERROR(Dashboard!W20,0) -> 84 | N36: Editable Variables | O36: Blue
C37: Total Hold Period (Fiscal Years) | E37: =ROUNDUP((E36)/12,1) -> 7 | N37: Formulas | O37: Black
C38: Sale Month | D38: =+E36+D22 -> 88 | E38: =EOMONTH(E22,E36) -> 49034 | F38: =+IFERROR(INDEX('(Z+) Monthly CF'!$F$9:$HB$9,1,MATCH(Inputs!$D38,'(Z+) Monthly CF'!$F$5:$HB$5,0)),0) -> 1.1960464 | G38: =+IFERROR(INDEX('(Z+) Monthly CF'!$F$10:$HB$10,1,MATCH(Inputs!D38,'(Z+) Monthly CF'!$F$5:$HB$5,0)),0) -> 1.2346843

Sheet Dashboard
A1: Project Overview
A3: Project Info | D3: Total Uses | F3: /Unit | G3: Percentage | I3: Assumed Exit Cap Rate | K3: IRR | M3: Year | O3: =IFERROR(1,0) -> 1 | P3: =IFERROR(O3+1,0) -> 2 | Q3: =IFERROR(P3+1,0) -> 3 | R3: =IFERROR(Q3+1,0) -> 4 | S3: =IFERROR(R3+1,0) -> 5 | T3: =IFERROR(S3+1,0) -> 6 | U3: =IFERROR(T3+1,0) -> 7 | V3: =IFERROR(U3+1,0) -> 8
A4: Address | B4: =Inputs!D6 -> 2828 STANFORD AVE | D4: Land Acquistions | E4: =IFERROR(Inputs!G6,0) -> 1601600 | F4: =IFERROR(E4/$B$10,0) -> 7150 | G4: =IFERROR(E4/$E$10,0) -> 0.026614551 | I4: Best case | J4: =IFERROR(J5-0.005,0) -> 0.0625 | K4: =IFERROR(22.1/100,0) -> 0.221 | M4: Date | O4: =IFERROR(TEXT(Inputs!E22, "yyyy"),0) -> 2027 | P4: =IFERROR(TEXT(Inputs!E22+365, "yyyy"),0) -> 2028 | Q4: =IFERROR(TEXT(Inputs!E22+(365*2), "yyyy"),0) -> 2029 | R4: =IFERROR(TEXT(Inputs!E22+(365*3), "yyyy"),0) -> 2030 | S4: =IFERROR(TEXT(Inputs!E22+(365*4),"yyyy"),0) -> 2031 | T4: =IFERROR(TEXT(Inputs!E22+(365*5), "yyyy"),0) -> 2032 | U4: =IFERROR(TEXT(Inputs!E22+(365*6), "yyyy"),0) -> 2033 | V4: =IFERROR(TEXT(Inputs!E22+(365*7), "yyyy"),0) -> 2034
A5: Levered IRR | B5: ='(Z+) Financing'!K7 -> 0.15538478 | D5: Modular Cost | E5: =IFERROR('(Z+) Dev Budget'!G14,0) -> 20160000 | F5: =IFERROR(E5/$B$10,0) -> 90000 | G5: =IFERROR(E5/$E$10,0) -> 0.33500833 | I5: Base Case | J5: 0.0675 | K5: =IFERROR(B5,0) -> 0.15538478 | M5: Project Costs | O5: =IFERROR(SUMIF('(Z+) Monthly CF'!F6:EU6,"=1",'(Z+) Monthly CF'!F70:EU70),0) -> -27147049 | P5: =IFERROR(SUMIF('(Z+) Monthly CF'!F6:EU6,"=2",'(Z+) Monthly CF'!F70:EU70),0) -> -24769287 | Q5: =IFERROR(SUMIF('(Z+) Monthly CF'!F6:EU6,"=3",'(Z+) Monthly CF'!F70:EU70),0) -> 0 | R5: =IFERROR(SUMIF('(Z+) Monthly CF'!F6:EU6,"=4",'(Z+) Monthly CF'!F70:EU70),0) -> 0 | S5: =IFERROR(SUMIF('(Z+) Monthly CF'!F6:EU6,"=5",'(Z+) Monthly CF'!F70:EU70),0) -> 0 | T5: =IFERROR(SUMIF('(Z+) Monthly CF'!F6:EU6,"=6",'(Z+) Monthly CF'!F70:EU70),0) -> 0 | U5: =IFERROR(SUMIF('(Z+) Monthly CF'!F6:EU6,"=8",'(Z+) Monthly CF'!F70:EU70),0) -> 0 | V5: =IFERROR(SUMIF('(Z+) Monthly CF'!G6:EV6,"=7",'(Z+) Monthly CF'!G70:EV70),0) -> 0
A6: Equity Multiple | B6: ='(Z+) Financing'!K12 -> 1.7201935 | D6: On-Site Hard Costs | E6: =IFERROR(Inputs!G7-'(Z+) Dev Budget'!G14,0) -> 23903340 | F6: =IFERROR(E6/$B$10,0) -> 106711.34 | G6: =IFERROR(E6/$E$10,0) -> 0.39721319 | I6: Worst Case | J6: =IFERROR(J5+0.005,0) -> 0.0725 | K6: =IFERROR(12.6/100,0) -> 0.126 | M6: Constr. Loan Proceeds | O6: =IFERROR(SUMIF('(Z+) Monthly CF'!F6:EU6,"=1",'(Z+) Monthly CF'!F89:EU89),0) -> 3305440.6 | P6: =IFERROR(SUMIF('(Z+) Monthly CF'!F6:EU6,"=2",'(Z+) Monthly CF'!F89:EU89),0) -> 24769287 | Q6: =IFERROR(SUMIF('(Z+) Monthly CF'!F6:EU6,"=3",'(Z+) Monthly CF'!F89:EU89),0) -> 0 | R6: =IFERROR(SUMIF('(Z+) Monthly CF'!F6:EU6,"=4",'(Z+) Monthly CF'!F89:EU89),0) -> 0 | S6: =IFERROR(SUMIF('(Z+) Monthly CF'!F6:EV6,"=5",'(Z+) Monthly CF'!F89:EV89),0) -> 0 | T6: =IFERROR(SUMIF('(Z+) Monthly CF'!F6:EW6,"=6",'(Z+) Monthly CF'!F89:EW89),0) -> 0 | U6: =IFERROR(SUMIF('(Z+) Monthly CF'!F6:EX6,"=7",'(Z+) Monthly CF'!F89:EX89),0) -> 0 | V6: =IFERROR(SUMIF('(Z+) Monthly CF'!G6:EY6,"=8",'(Z+) Monthly CF'!G89:EY89),0) -> 0
A7: Cash-on-Cash Return | B7: ='(Z+) Financing'!K9 -> 0.17628922 | D7: Soft Costs | E7: =IFERROR(Inputs!G8,0) -> 3635373 | F7: =IFERROR(E7/$B$10,0) -> 16229.344 | G7: =IFERROR(E7/$E$10,0) -> 0.060410726 | M7: Constr. Loan Re-Payment | O7: =IFERROR(SUMIF('(Z+) Monthly CF'!F6:EU6,"=1",'(Z+) Monthly CF'!F92:EU92)+SUMIF('(Z+) Monthly CF'!F6:EU6,"=1",'(Z+) Monthly CF'!F77:EU77),0) -> 5578.6791 | P7: =IFERROR(SUMIF('(Z+) Monthly CF'!G6:EV6,"=2",'(Z+) Monthly CF'!G92:EV92)-SUMIF('(Z+) Monthly CF'!G6:EV6,"=2",'(Z+) Monthly CF'!G77:EV77),0) -> -1895624.3 | Q7: =IFERROR(SUMIF('(Z+) Monthly CF'!H6:EW6,"=3",'(Z+) Monthly CF'!H92:EW92)-SUMIF('(Z+) Monthly CF'!H6:EW6,"=3",'(Z+) Monthly CF'!H77:EW77),0) -> -34312336 | R7: =IFERROR(SUMIF('(Z+) Monthly CF'!I6:EX6,"=4",'(Z+) Monthly CF'!I92:EX92)-SUMIF('(Z+) Monthly CF'!I6:EX6,"=4",'(Z+) Monthly CF'!I77:EX77),0) -> 0 | S7: =IFERROR(SUMIF('(Z+) Monthly CF'!G6:EV6,"=5",'(Z+) Monthly CF'!G92:EV92)-SUMIF('(Z+) Monthly CF'!I6:EX6,"=5",'(Z+) Monthly CF'!I77:EX77),0) -> 0 | T7: =IFERROR(SUMIF('(Z+) Monthly CF'!H6:EW6,"=6",'(Z+) Monthly CF'!H92:EW92)-SUMIF('(Z+) Monthly CF'!I6:EX6,"=6",'(Z+) Monthly CF'!I77:EX77),0) -> 0 | U7: =IFERROR(SUMIF('(Z+) Monthly CF'!I6:EX6,"=7",'(Z+) Monthly CF'!I92:EX92)-SUMIF('(Z+) Monthly CF'!I6:EX6,"=7",'(Z+) Monthly CF'!I77:EX77),0) -> 0 | V7: =IFERROR(SUMIF('(Z+) Monthly CF'!J6:EY6,"=8",'(Z+) Monthly CF'!J92:EY92)-SUMIF('(Z+) Monthly CF'!I6:EX6,"=8",'(Z+) Monthly CF'!I77:EX77),0) -> 0
A8: Untrended Return-on-Cost | B8: ='(Z+) Financing'!K11 -> 0.080198049 | D8: Admin Costs | E8: =IFERROR(Inputs!G9,0) -> 2608935.6 | F8: =IFERROR(E8/$B$10,0) -> 11647.034 | G8: =IFERROR(E8/$E$10,0) -> 0.043353927 | I8: Financing | J8: Constr. | K8: Perm. | M8: Gross Rental Income | O8: =IFERROR(SUMIF('(Z+) Monthly CF'!F6:EU6, "=1",'(Z+) Monthly CF'!F19:EU19),0) -> 0 | P8: =IFERROR(SUMIF('(Z+) Monthly CF'!G6:EV6, "=2",'(Z+) Monthly CF'!G19:EV19),0) -> 356945.09 | Q8: =IFERROR(SUMIF('(Z+) Monthly CF'!H6:EW6, "=3",'(Z+) Monthly CF'!H19:EW19),0) -> 5618733.6 | R8: =IFERROR(SUMIF('(Z+) Monthly CF'!I6:EX6, "=4",'(Z+) Monthly CF'!I19:EX19),0) -> 6683635.6 | S8: =IFERROR(SUMIF('(Z+) Monthly CF'!J6:EY6, "=5",'(Z+) Monthly CF'!J19:EY19),0) -> 6850726.5 | T8: =IFERROR(SUMIF('(Z+) Monthly CF'!K6:EZ6, "=6",'(Z+) Monthly CF'!K19:EZ19),0) -> 7021994.7 | U8: =IFERROR(SUMIF('(Z+) Monthly CF'!L6:FA6, "=7",'(Z+) Monthly CF'!L19:FA19),0) -> 7197544.5 | V8: =IFERROR(SUMIF('(Z+) Monthly CF'!M6:FB6, "=8",'(Z+) Monthly CF'!M19:FB19),0) -> 7377483.1
A9: Total Profit | B9: ='(Z+) Financing'!K14 -> 17170572 | D9: Financing Costs | E9: =IFERROR(Inputs!G10,0) -> 8268359.9 | F9: =IFERROR(E9/$B$10,0) -> 36912.321 | G9: =IFERROR(E4/$E$10,0) -> 0.026614551 | I9: Loan Proceeds | J9: =IFERROR('(Z+) Financing'!D38,0) -> 36336000 | K9: =IFERROR(perm_proceeds,0) -> 48142000 | M9: Operating Expenses | O9: =IFERROR(SUMIF('(Z+) Monthly CF'!F6:EU6,"=1",'(Z+) Monthly CF'!F47:EU47),0) -> 0 | P9: =IFERROR(SUMIF('(Z+) Monthly CF'!G6:EV6,"=2",'(Z+) Monthly CF'!G47:EV47),0) -> -322257.24 | Q9: =IFERROR(SUMIF('(Z+) Monthly CF'!H6:EW6,"=3",'(Z+) Monthly CF'!H47:EW47),0) -> -1645829.5 | R9: =IFERROR(SUMIF('(Z+) Monthly CF'!I6:EX6,"=4",'(Z+) Monthly CF'!I47:EX47),0) -> -1766930.5 | S9: =IFERROR(SUMIF('(Z+) Monthly CF'!J6:EY6,"=5",'(Z+) Monthly CF'!J47:EY47),0) -> -1817346.4 | T9: =IFERROR(SUMIF('(Z+) Monthly CF'!K6:EZ6,"=6",'(Z+) Monthly CF'!K47:EZ47),0) -> -1869206 | U9: =IFERROR(SUMIF('(Z+) Monthly CF'!L6:FA6,"=7",'(Z+) Monthly CF'!L47:FA47),0) -> -1922550.7 | V9: =IFERROR(SUMIF('(Z+) Monthly CF'!M6:FB6,"=8",'(Z+) Monthly CF'!M47:FB47),0) -> -1977423.2
A10: Unit Count | B10: =Inputs!O10 -> 224 | D10: Total | E10: =IFERROR(SUM(E4:E9),0) -> 60177608 | F10: =IFERROR(SUM(F4:F9),0) -> 268650.04 | G10: =IFERROR(SUM(G4:G9),0) -> 0.88921527 | I10: LTV | J10: =IFERROR('(Z+) Financing'!D34,0) -> 0.75 | K10: =IFERROR('(Z+) Financing'!H14,0) -> 0.75 | M10: NOI | O10: =IFERROR(Dashboard!O8+Dashboard!O9,0) -> 0 | P10: =IFERROR(Dashboard!P8+Dashboard!P9,0) -> 34687.856 | Q10: =IFERROR(Dashboard!Q8+Dashboard!Q9,0) -> 3972904.1 | R10: =IFERROR(Dashboard!R8+Dashboard!R9,0) -> 4916705.1 | S10: =IFERROR(Dashboard!S8+Dashboard!S9,0) -> 5033380.1 | T10: =IFERROR(Dashboard!T8+Dashboard!T9,0) -> 5152788.7 | U10: =IFERROR(Dashboard!U8+Dashboard!U9,0) -> 5274993.8 | V10: =IFERROR(SUM(V8:V9),0) -> 5400059.9
A11: Parking | B11: =Inputs!H16 -> 38 | I11: LTC | J11: 0.7 | K11: =IFERROR('(Z+) Financing'!H16,0) -> 0.8 | M11: Perm. Loan Proceeds | O11: =IFERROR(SUMIF('(Z+) Monthly CF'!F6:EU6,"=1",'(Z+) Monthly CF'!F95:EU95),0) -> 0 | P11: =IFERROR(SUMIF('(Z+) Monthly CF'!G6:EV6,"=2",'(Z+) Monthly CF'!G95:EV95),0) -> 0 | Q11: =IFERROR(SUMIF('(Z+) Monthly CF'!H6:EW6,"=3",'(Z+) Monthly CF'!H95:EW95),0) -> 48137186 | R11: =IFERROR(SUMIF('(Z+) Monthly CF'!I6:EX6,"=4",'(Z+) Monthly CF'!I95:EX95),0) -> 0 | S11: =IFERROR(SUMIF('(Z+) Monthly CF'!J6:EY6,"=5",'(Z+) Monthly CF'!J95:EY95),0) -> 0 | T11: =IFERROR(SUMIF('(Z+) Monthly CF'!K6:EZ6,"=6",'(Z+) Monthly CF'!K95:EZ95),0) -> 0 | U11: =IFERROR(SUMIF('(Z+) Monthly CF'!L6:FA6,"=7",'(Z+) Monthly CF'!L95:FA95),0) -> 0 | V11: =IFERROR(SUMIF('(Z+) Monthly CF'!M6:FB6,"=8",'(Z+) Monthly CF'!M95:FB95),0) -> 0
A12: NRSF | B12: =Inputs!D17 -> 101416 | D12: Total Sources | F12: /Unit | G12: Percentage | I12: Int. Rate | J12: 0.09 | K12: 0.0575 | M12: Debt Service | O12: =IFERROR((SUMIF('(Z+) Monthly CF'!F6:EU6,"=1",'(Z+) Monthly CF'!F96:EU96))+SUMIF('(Z+) Monthly CF'!F6:EU6,"=1",'(Z+) Monthly CF'!F97:EU97),0) -> 0 | P12: =IFERROR((SUMIF('(Z+) Monthly CF'!G6:EV6,"=2",'(Z+) Monthly CF'!G96:EV96))+SUMIF('(Z+) Monthly CF'!G6:EV6,"=2",'(Z+) Monthly CF'!G97:EV97),0) -> 0 | Q12: =IFERROR((SUMIF('(Z+) Monthly CF'!H6:EW6,"=3",'(Z+) Monthly CF'!H96:EW96))+SUMIF('(Z+) Monthly CF'!H6:EW6,"=3",'(Z+) Monthly CF'!H97:EW97),0) -> -807451.15 | R12: =IFERROR((SUMIF('(Z+) Monthly CF'!I6:EX6,"=4",'(Z+) Monthly CF'!I96:EX96))+SUMIF('(Z+) Monthly CF'!I6:EX6,"=4",'(Z+) Monthly CF'!I97:EX97),0) -> -3229804.6 | S12: =IFERROR((SUMIF('(Z+) Monthly CF'!J6:EY6,"=5",'(Z+) Monthly CF'!J96:EY96))+SUMIF('(Z+) Monthly CF'!J6:EY6,"=5",'(Z+) Monthly CF'!J97:EY97),0) -> -3229804.6 | T12: =IFERROR((SUMIF('(Z+) Monthly CF'!K6:EZ6,"=6",'(Z+) Monthly CF'!K96:EZ96))+SUMIF('(Z+) Monthly CF'!K6:EZ6,"=6",'(Z+) Monthly CF'!K97:EZ97),0) -> -3229804.6 | U12: =IFERROR((SUMIF('(Z+) Monthly CF'!L6:FA6,"=7",'(Z+) Monthly CF'!L96:FA96))+SUMIF('(Z+) Monthly CF'!L6:FA6,"=7",'(Z+) Monthly CF'!L97:FA97),0) -> -3229804.6 | V12: =IFERROR((SUMIF('(Z+) Monthly CF'!M6:FB6,"=8",'(Z+) Monthly CF'!M96:FB96))+SUMIF('(Z+) Monthly CF'!M6:FB6,"=8",'(Z+) Monthly CF'!M97:FB97),0) -> -1076601.5
A13: Total Development Cost | B13: =Inputs!G11 -> 60177608 | D13: Equity | E13: =IFERROR(Inputs!L19,0) -> 23841608 | F13: =IFERROR(E13/B10,0) -> 106435.75 | G13: =IFERROR(E13/$E$15,0) -> 0.39618737 | I13: DSCR | J13: N/A | K13: =IFERROR('(Z+) Financing'!H11,0) -> 1.2 | M13: Perm. Loan Re-Payment | O13: =IFERROR(SUMIF('(Z+) Monthly CF'!I6:EX6,"=1",'(Z+) Monthly CF'!F98:EX98),0) -> 0 | P13: =IFERROR(SUMIF('(Z+) Monthly CF'!G6:EY6,"=2",'(Z+) Monthly CF'!G98:EY98),0) -> 0 | Q13: =IFERROR(SUMIF('(Z+) Monthly CF'!H6:EZ6,"=3",'(Z+) Monthly CF'!H98:EZ98),0) -> 0 | R13: =IFERROR(SUMIF('(Z+) Monthly CF'!I6:FA6,"=4",'(Z+) Monthly CF'!I98:FA98),0) -> 0 | S13: =IFERROR(SUMIF('(Z+) Monthly CF'!J6:FB6,"=5",'(Z+) Monthly CF'!J98:FB98),0) -> 0 | T13: =IFERROR(SUMIF('(Z+) Monthly CF'!K6:FC6,"=6",'(Z+) Monthly CF'!K98:FC98),0) -> 0 | U13: =IFERROR(SUMIF('(Z+) Monthly CF'!L6:FD6,"=7",'(Z+) Monthly CF'!L98:FD98),0) -> 0 | V13: =IFERROR(SUMIF('(Z+) Monthly CF'!F6:FE6,"=8",'(Z+) Monthly CF'!F98:FE98),0) -> -45934519
A14: Price per Unit | B14: =Inputs!H11 -> 268650.04 | D14: Debt | E14: =IFERROR(SUM(Inputs!L20),0) -> 36336000 | F14: =IFERROR(E14/B10,0) -> 162214.29 | G14: =IFERROR(E14/$E$15,0) -> 0.60381263 | M14: Sale Proceeds | O14: =IFERROR(SUMIF('(Z+) Monthly CF'!F6:EW6,"=1",'(Z+) Monthly CF'!F54:EW54),0) -> 0 | P14: =IFERROR(SUMIF('(Z+) Monthly CF'!G6:EX6,"=2",'(Z+) Monthly CF'!G54:EX54),0) -> 0 | Q14: =IFERROR(SUMIF('(Z+) Monthly CF'!H6:EY6,"=3",'(Z+) Monthly CF'!H54:EY54),0) -> 0 | R14: =IFERROR(SUMIF('(Z+) Monthly CF'!I6:EZ6,"=4",'(Z+) Monthly CF'!I54:EZ54),0) -> 0 | S14: =IFERROR(SUMIF('(Z+) Monthly CF'!J6:FA6,"=5",'(Z+) Monthly CF'!J54:FA54),0) -> 0 | T14: =IFERROR(SUMIF('(Z+) Monthly CF'!K6:FB6,"=6",'(Z+) Monthly CF'!K54:FB54),0) -> 0 | U14: =IFERROR(SUMIF('(Z+) Monthly CF'!L6:FC6,"=7",'(Z+) Monthly CF'!L54:FC54),0) -> 0 | V14: =IFERROR(SUMIF('(Z+) Monthly CF'!M6:FD6,"=8",'(Z+) Monthly CF'!M54:FD54),0) -> 59724978
A15: Construction Type | B15: Modular | D15: Total | E15: =IFERROR(Inputs!L21,0) -> 60177608 | F15: =IFERROR(E15/B10,0) -> 268650.04 | G15: =IFERROR(SUM(G13:G14),0) -> 1 | M15: Levered Cash Flow | O15: =IFERROR(SUM(O5:O14),0) -> -23836030 | P15: =IFERROR(SUM(P5:P14),0) -> -1826248.5 | Q15: =IFERROR(SUM(Q5:Q14),0) -> 20963207 | R15: =IFERROR(SUM(R5:R14),0) -> 6603605.6 | S15: =IFERROR(SUM(S5:S14),0) -> 6836955.6 | T15: =IFERROR(SUM(T5:T14),0) -> 7075772.8 | U15: =IFERROR(SUM(U5:U14),0) -> 7320183.1 | V15: =IFERROR(SUM(V5:V14),0) -> 23513978
A17: IRR% - Construction Loan LTC vs Interest Rate | I17: IRR% - Hold Period vs Exit Cap | Q17: Operating Assumptions | R17: /Unit /Month | S17: Annual | T17: /Unit | V17: Drivers
A18: IRR% | E18: Interest Rate | I18: IRR% | M18: Exit Cap | Q18: Rent | R18: =IFERROR('(Z+) OpEx'!J31/Dashboard!B10/12,0) -> 2444.7968 | S18: =R18*12*$B$10 -> 6571613.8 | T18: =IFERROR(S18/$B$10,0) -> 29337.562 | V18: OnSite$ | W18: 90000
B19: ='(Z+) Monthly CF'!F103 -> 0.15538478 | C19: =E19-0.02 -> 0.07 | D19: =E19-0.01 -> 0.08 | E19: =9/100 -> 0.09 | F19: =E19+0.01 -> 0.1 | G19: =F19+0.01 -> 0.11 | J19: ='(Z+) Monthly CF'!F103 -> 0.15538478 | K19: =IFERROR(L19-0.25%,0) -> 0.0625 | L19: =IFERROR(M19-0.25%,0) -> 0.065 | M19: =IFERROR(6.75/100,0) -> 0.0675 | N19: =IFERROR(M19+0.25%,0) -> 0.07 | O19: =IFERROR(N19+0.25%,0) -> 0.0725 | Q19: Other Income | R19: =IFERROR('(Z+) OpEx'!J33/B10/12,0) -> 66.822844 | S19: =IFERROR('(Z+) OpEx'!J33,0) -> 179619.8 | T19: =IFERROR(S19/$B$10,0) -> 801.87412 | V19: Constr. Time | W19: 11
B20: =IFERROR(B21+0.05,0) -> 0.8 | C20: 0.17508472 | D20: 0.16905209 | E20: 0.1635294 | F20: 0.15849965 | G20: 0.15396062 | J20: =IFERROR(J21-12,0) -> 60 | K20: 0.18505458 | L20: 0.16565065 | M20: 0.14619973 | N20: 0.12658924 | O20: 0.10669253 | Q20: Total Rental Income | R20: =IFERROR(SUM(R18:R19),0) -> 2511.6196 | S20: =IFERROR(SUM(S18:S19),0) -> 6751233.6 | T20: =IFERROR(S20/$B$10,0) -> 30139.436 | V20: Hold Period | W20: 84
B21: =IFERROR(B22+0.05,0) -> 0.75 | C21: 0.16903169 | D21: 0.16388296 | E21: 0.15916845 | F21: 0.15487793 | G21: 0.15104044 | J21: =IFERROR(J22-12,0) -> 72 | K21: 0.18146794 | L21: 0.16638525 | M21: 0.15126211 | N21: 0.13601667 | O21: 0.12055787 | Q21: Vacancy & Credit Loss | R21: =IFERROR('(Z+) OpEx'!K34/B10/12,0) -> -73.343904 | S21: =IFERROR('(Z+) OpEx'!J34,0) -> -197148.41 | T21: =IFERROR(S21/$B$10,0) -> -880.12685 | V21: Rent Growth | W21: 0.025
A22: Constr. LTC | B22: =70/100 -> 0.7 | C22: 0.16370944 | D22: 0.15934016 | E22: 0.15538478 | F22: 0.15176193 | G22: 0.14847781 | I22: Hold Period | J22: =IFERROR(84,0) -> 84 | K22: 0.17922924 | L22: 0.16730761 | M22: 0.15538478 | N22: 0.14340383 | O22: 0.13130299 | Q22: Effective Gross Income | R22: =IFERROR(SUM(R20:R21),0) -> 2438.2757 | S22: =IFERROR(SUM(S20:S21),0) -> 6554085.2 | T22: =IFERROR(S22/$B$10,0) -> 29259.309
B23: =IFERROR(B22-5%,0) -> 0.65 | C23: 0.15911227 | D23: 0.15544184 | E23: 0.15205938 | F23: 0.14896865 | G23: 0.14618538 | J23: =IFERROR(J22+12,0) -> 96 | K23: 0.17784042 | L23: 0.16830321 | M23: 0.15880408 | N23: 0.1493039 | O23: 0.13976169 | Q23: Operating Expenses | R23: =IFERROR('(Z+) OpEx'!J36/B10/12,0) -> -642.84165 | S23: =IFERROR('(Z+) OpEx'!J36,0) -> -1727958.3 | T23: =IFERROR(S23/$B$10,0) -> -7714.0998
B24: =IFERROR(B23-5%,0) -> 0.6 | C24: 0.15504945 | D24: 0.1519296 | E24: 0.14910477 | F24: 0.14651422 | G24: 0.14416016 | J24: =IFERROR(J23+12,0) -> 108 | K24: 0.17697797 | L24: 0.1692821 | M24: 0.16165414 | N24: 0.154067 | O24: 0.14649333 | Q24: Property Tax Exemption | R24: Yes | S24: =IFERROR(0,0) -> 0 | T24: =IFERROR(S24/B10,0) -> 0
Q25: NOI | R25: =IFERROR(SUM(R22:R23),0) -> 1795.4341 | S25: =R25*12*$B$10 -> 4826126.8 | T25: =IFERROR(S25/$B$10,0) -> 21545.209
A26: IRR% - Constr. Timeline vs On-Site Cost | I26: IRR % - Hold Period vs Perm. Interest Rate
A27: IRR% | E27: On-site Cost $/unit | I27: IRR% | M27: Perm Int. Rate
B28: ='(Z+) Monthly CF'!F103 -> 0.15538478 | C28: =IFERROR(E28-20000,0) -> 70000 | D28: =IFERROR(E28-10000,0) -> 80000 | E28: =IFERROR(90000,0) -> 90000 | F28: =IFERROR(E28+10000,0) -> 100000 | G28: =IFERROR(F28+10000,0) -> 110000 | J28: ='(Z+) Monthly CF'!F103 -> 0.15538478 | K28: =IFERROR(L28-0.25%,0) -> 0.0525 | L28: =IFERROR(M28-0.25%,0) -> 0.055 | M28: =IFERROR(5.75/100,0) -> 0.0575 | N28: =IFERROR(M28+0.25%,0) -> 0.06 | O28: =IFERROR(N28+0.25%,0) -> 0.0625
B29: =IFERROR(B31-4,0) -> 7 | C29: 0.23031353 | D29: 0.2048513 | E29: 0.17895251 | F29: 0.15224361 | G29: 0.12424155 | J29: =IFERROR(J30-12,0) -> 60 | K29: 0.15257681 | L29: 0.14940372 | M29: 0.14619973 | N29: 0.14296493 | O29: 0.13969936
B30: =IFERROR(B31-2,0) -> 9 | C30: 0.21621862 | D30: 0.19159481 | E30: 0.16655741 | F30: 0.14070632 | G30: 0.11352964 | J30: =IFERROR(J31-12,0) -> 72 | K30: 0.15860149 | L30: 0.15495571 | M30: 0.15126211 | N30: 0.14752056 | O30: 0.14373096
A31: Construction Timeline | B31: =IFERROR(11,0) -> 11 | C31: 0.20355343 | D31: 0.17966238 | E31: 0.15538446 | F31: 0.13024003 | G31: 0.10380639 | I31: Hold Period | J31: =IFERROR(84,0) -> 84 | K31: 0.1633119 | L31: 0.15937983 | M31: 0.15538478 | N31: 0.15132635 | O31: 0.14720411
B32: =IFERROR(B31+2,0) -> 13 | C32: 0.19208373 | D32: 0.1688492 | E32: 0.14517463 | F32: 0.12065169 | G32: 0.094870414 | J32: =IFERROR(J31+12,0) -> 96 | K32: 0.16707755 | L32: 0.16297862 | M32: 0.15880408 | N32: 0.15455317 | O32: 0.1502251
B33: =IFERROR(B32+2,0) -> 15 | C33: 0.18148727 | D33: 0.15882171 | E33: 0.13568382 | F33: 0.11171451 | G33: 0.085550992 | J33: =IFERROR(J32+12,0) -> 108 | K33: 0.17011494 | L33: 0.16592736 | M33: 0.16165414 | N33: 0.15729421 | O33: 0.15284641
A35: IRR% - Rent Growth vs Exit Cap | I35: IRR % - Hold Period vs Constr. Interest Rate
A36: IRR% | E36: Exit Cap | I36: IRR% | M36: Contstruction Int. Rate
B37: ='(Z+) Monthly CF'!F103 -> 0.15538478 | C37: =IFERROR(D37-0.0025,0) -> 0.0625 | D37: =IFERROR(E37-0.0025,0) -> 0.065 | E37: =IFERROR(6.75/100,0) -> 0.0675 | F37: =IFERROR(E37+0.0025,0) -> 0.07 | G37: =IFERROR(F37+0.0025,0) -> 0.0725 | J37: ='(Z+) Monthly CF'!F103 -> 0.15538478 | K37: =IFERROR(L37-0.25%,0) -> 0.085 | L37: =IFERROR(M37-0.25%,0) -> 0.0875 | M37: =IFERROR(9/100,0) -> 0.09 | N37: =IFERROR(M37+0.25%,0) -> 0.0925 | O37: =IFERROR(N37+0.25%,0) -> 0.095
B38: =IFERROR(B39+0.01,0) -> 0.045 | C38: 0.20007318 | D38: 0.1892186 | E38: 0.17844735 | F38: 0.16771751 | G38: 0.15698611 | J38: =IFERROR(J39-12,0) -> 60 | K38: 0.14893566 | L38: 0.14755359 | M38: 0.14619973 | N38: 0.1448719 | O38: 0.14357423
B39: =IFERROR(B40+0.01,0) -> 0.035 | C39: 0.18957965 | D39: 0.17820111 | E39: 0.16686664 | F39: 0.15552765 | G39: 0.14413291 | J39: =IFERROR(J40-12,0) -> 72 | K39: 0.1535418 | L39: 0.15239009 | M39: 0.15126211 | N39: 0.15015522 | O39: 0.14907457
A40: Rent Growth Post-Occ | B40: =IFERROR(2.5/100,0) -> 0.025 | C40: 0.17922924 | D40: 0.16730761 | E40: 0.15538478 | F40: 0.14340383 | G40: 0.13130299 | I40: Hold Period | J40: =IFERROR(84,0) -> 84 | K40: 0.15731899 | L40: 0.15634142 | M40: 0.15538478 | N40: 0.15444615 | O40: 0.15353143
B41: =IFERROR(B40-0.01,0) -> 0.015 | C41: 0.16902912 | D41: 0.15654564 | E41: 0.14400926 | F41: 0.1313527 | G41: 0.11850087 | J41: =IFERROR(J40+12,0) -> 96 | K41: 0.16047235 | L41: 0.15962865 | M41: 0.15880408 | N41: 0.15799542 | O41: 0.15720915
B42: =IFERROR(B40-0.02,0) -> 0.005 | C42: 0.15898654 | D42: 0.14592304 | E42: 0.13274801 | F42: 0.11938151 | G42: 0.10573165 | J42: =IFERROR(J41+12,0) -> 108 | K42: 0.16311449 | L42: 0.16237538 | M42: 0.16165414 | N42: 0.16094735 | O42: 0.1602619

Sheet (Z+) Dev Budget
C3: Development Budget
C5: Category | E5: Factor | F5: Unit | G5: Budget | H5: $/GSF | I5: $/NRSF | J5: $/LSF | K5: $/Unit | L5: % of Tot.
C6: Acquisition Costs
C7: Land Cost | G7: 1600000 | H7: =IFERROR(G7/Inputs!$D$16,0) -> 117.79864 | I7: =IFERROR(G7/Inputs!$D$17,0) -> 15.776603 | J7: =IFERROR(G7/Inputs!$D$13,0) -> 54.270402 | K7: =IFERROR(G7/Inputs!$H$14,0) -> 7142.8571 | L7: =IFERROR(G7/$G$127,0) -> 0
C8: Escrow/Closing | E8: =IFERROR(0.1/100,0) -> 0.001 | G8: =IFERROR(G7*E8,0) -> 1600 | H8: =IFERROR(G8/Inputs!$D$16,0) -> 0.11779864 | I8: =IFERROR(G8/Inputs!$D$17,0) -> 0.015776603 | J8: =IFERROR(G8/Inputs!$D$13,0) -> 0.054270402 | K8: =IFERROR(G8/Inputs!$H$14,0) -> 7.1428571 | L8: =IFERROR(G8/$G$126,0) -> 2.6587963e-05
C9: Acquisition Fee | E9: =IFERROR(0/100,0) -> 0 | G9: =IFERROR(0,0) -> 0 | H9: =IFERROR(G9/Inputs!$D$16,0) -> 0 | I9: =IFERROR(G9/Inputs!$D$17,0) -> 0 | J9: =IFERROR(G9/Inputs!$D$13,0) -> 0 | K9: =IFERROR(G9/Inputs!H14,0) -> 0 | L9: =IFERROR(G9/$G$126,0) -> 0
C10: Total Acquisition Costs | E10: =IFERROR(0,0) -> 0 | G10: =IFERROR(SUM(G7:G9),0) -> 1601600 | H10: =IFERROR(G10/Inputs!$D$16,0) -> 117.91644 | I10: =IFERROR(G10/Inputs!$D$17,0) -> 15.79238 | J10: =IFERROR(G10/Inputs!$D$13,0) -> 54.324673 | K10: =IFERROR(G10/Inputs!H14,0) -> 7150 | L10: =IFERROR(G10/$G$127,0) -> 0
C12: Hard Costs
C13: Module Costs
C14: 1-BED 1-BA (420 SF) | E14: =IFERROR(90000,0) -> 90000 | F14: DU | G14: =IFERROR(IFERROR(E14*Inputs!O11,0),0) -> 20160000 | H14: =IFERROR(G14/Inputs!$D$16,0) -> 1484.2628 | I14: =IFERROR(G14/Inputs!$D$17,0) -> 198.7852 | J14: =IFERROR(G14/Inputs!$D$13,0) -> 683.80707 | K14: =IFERROR(G14/Inputs!$H$14,0) -> 90000 | L14: =IFERROR(G14/$G$127,0) -> 0
C15: 2-BED 1-BA (840 SF) | E15: =IFERROR(160000,0) -> 160000 | F15: DU | G15: =IFERROR(E15*Inputs!O12, 0) -> 0 | L15: =IFERROR(G15/$G$126,0) -> 0
C16: 3-BED 2-BA (840 SF) | E16: =IFERROR(180000,0) -> 180000 | F16: DU | G16: =IFERROR(E16*Inputs!O13,0) -> 0 | L16: =IFERROR(G16/$G$126,0) -> 0
C17: Service Mods | E17: =IFERROR(75000,0) -> 75000 | F17: DU | G17: =IFERROR(E17*SUM(Inputs!O16:O20),0) -> 0 | H17: =IFERROR(G17/Inputs!$D$16,0) -> 0 | I17: =IFERROR(G17/Inputs!$D$17,0) -> 0 | J17: =IFERROR(G17/Inputs!$D$13,0) -> 0 | K17: =IFERROR(G17/Inputs!$H$14,0) -> 0 | L17: =IFERROR(G17/$G$126,0) -> 0
C18: Staircases | E18: =IFERROR(15000,0) -> 15000 | F18: DU | G18: =IFERROR(E18*Inputs!O15,0) -> 255000 | H18: =IFERROR(G18/Inputs!$D$16,0) -> 18.774158 | I18: =IFERROR(G18/Inputs!$D$17,0) -> 2.5143962 | J18: =IFERROR(G18/Inputs!$D$13,0) -> 8.6493454 | K18: =IFERROR(G18/Inputs!$H$14,0) -> 1138.3929 | L18: =IFERROR(G18/$G$126,0) -> 0.0042374565
C19: Onsite Costs | E19: =IFERROR(Dashboard!W18,0) -> 90000 | F19: DU | G19: =IFERROR(E19*Inputs!H14,0) -> 20160000 | H19: =IFERROR(G19/Inputs!$D$16,0) -> 1484.2628 | I19: =IFERROR(G19/Inputs!$D$17,0) -> 198.7852 | J19: =IFERROR(G19/Inputs!$D$13,0) -> 683.80707 | K19: =IFERROR(G19/Inputs!$H$14,0) -> 90000 | L19: =IFERROR(G19/$G$126,0) -> 0.33500833
C20: Podium Cost | E20: =IFERROR(105,0) -> 105 | F20: Footprint SF | G20: =IFERROR(Inputs!O8*E20*Inputs!O7,0) -> 1500345 | H20: =IFERROR(G20/Inputs!$D$16,0) -> 110.46162 | I20: =IFERROR(G20/Inputs!$D$17,0) -> 14.793967 | J20: =IFERROR(G20/Inputs!$D$13,0) -> 50.890204 | K20: =IFERROR(G20/Inputs!$H$14,0) -> 6697.9688 | L20: =IFERROR(G20/$G$126,0) -> 0.024931948
C21: Transport & Insurance | E21: =IFERROR(1500,0) -> 1500 | F21: DU | G21: =IFERROR(Inputs!H14*E21,0) -> 336000 | H21: =IFERROR(G21/Inputs!$D$16,0) -> 24.737714 | I21: =IFERROR(G21/Inputs!$D$17,0) -> 3.3130867 | J21: =IFERROR(G21/Inputs!$D$13,0) -> 11.396784 | K21: =IFERROR(G21/Inputs!$H$14,0) -> 1500 | L21: =IFERROR(G21/$G$126,0) -> 0.0055834721
C22: Cost Escalation Allowance | E22: =IFERROR((1+Inputs!L9)^(Inputs!E23/12)-1,0) -> 0.019803903 | F22: GC Contr | G22: =IFERROR(+E22*SUM(G19,G20),0) -> 428959.37 | H22: =IFERROR(G22/Inputs!$D$16,0) -> 31.581768 | I22: =IFERROR(G22/Inputs!$D$17,0) -> 4.2297011 | J22: =IFERROR(G22/Inputs!$D$13,0) -> 14.549873 | K22: =IFERROR(G22/Inputs!$H$14,0) -> 1914.9972 | L22: =IFERROR(G22/$G$126,0) -> 0.0071282222
C23: Subtotal - GC Contract Prelim | E23: =IFERROR(0,0) -> 0 | G23: =IFERROR(+SUM(G14:G22),0) -> 42840304 | H23: =IFERROR(G23/Inputs!$D$16,0) -> 3154.0809 | I23: =IFERROR(G23/Inputs!$D$17,0) -> 422.42155 | J23: =IFERROR(G23/Inputs!$D$13,0) -> 1453.1003 | K23: =IFERROR(G23/Inputs!$H$14,0) -> 191251.36 | L23: =IFERROR(G23/$G$126,0) -> 0.71189776
C24: Enviro Contingency | E24: =IFERROR(0,0) -> 0 | F24: DU | G24: =IFERROR(0,0) -> 0 | H24: =IFERROR(G24/Inputs!$D$16,0) -> 0 | I24: =IFERROR(G24/Inputs!$D$17,0) -> 0 | J24: =IFERROR(G24/Inputs!$D$13,0) -> 0 | K24: =IFERROR(G24/Inputs!$H$14,0) -> 0 | L24: =IFERROR(G24/$G$126,0) -> 0
C25: Owner's Construction Security | E25: =IFERROR(1600,0) -> 1600 | F25: Constr Mo | G25: =IFERROR(E25*Inputs!E26,0) -> 17600 | H25: =IFERROR(G25/Inputs!$D$16,0) -> 1.295785 | I25: =IFERROR(G25/Inputs!$D$17,0) -> 0.17354264 | J25: =IFERROR(G25/Inputs!$D$13,0) -> 0.59697443 | K25: =IFERROR(G25/Inputs!$H$14,0) -> 78.571429 | L25: =IFERROR(G25/$G$126,0) -> 0.00029246759
C26: Quality Control Peer (Inspections) | E26: =IFERROR(0,0) -> 0 | F26: DU | G26: =IFERROR(E26*Inputs!H14,0) -> 0 | H26: =IFERROR(G26/Inputs!$D$16,0) -> 0 | I26: =IFERROR(G26/Inputs!$D$17,0) -> 0 | J26: =IFERROR(G26/Inputs!$D$13,0) -> 0 | K26: =IFERROR(G26/Inputs!$H$14,0) -> 0 | L26: =IFERROR(G26/$G$126,0) -> 0
C27: Commercial / Tenant Improvements | E27: =IFERROR(0,0) -> 0 | F27: Comm NRSF | G27: =IFERROR(E27*Inputs!D17,0) -> 0 | H27: =IFERROR(G27/Inputs!$D$16,0) -> 0 | I27: =IFERROR(G27/Inputs!$D$17,0) -> 0 | J27: =IFERROR(G27/Inputs!$D$13,0) -> 0 | K27: =IFERROR(G27/Inputs!$H$14,0) -> 0 | L27: =IFERROR(G27/$G$126,0) -> 0
C28: Demolition | E28: =IFERROR(3,0) -> 3 | F28: Land SF | G28: =IFERROR(E28*Inputs!D13,0) -> 88446 | H28: =IFERROR(G28/Inputs!$D$16,0) -> 6.5117615 | I28: =IFERROR(G28/Inputs!$D$17,0) -> 0.87211091 | J28: =IFERROR(G28/Inputs!$D$13,0) -> 3 | K28: =IFERROR(G28/Inputs!$H$14,0) -> 394.84821 | L28: =IFERROR(G28/$G$126,0) -> 0.0014697493
C29: Owner's Contingency | E29: =IFERROR(5/100,0) -> 0.05 | G29: =IFERROR(+SUM(G23-G14-G22,G28)*E29,0) -> 1116989.6 | H29: =IFERROR(G29/Inputs!$D$16,0) -> 82.237405 | I29: =IFERROR(G29/Inputs!$D$17,0) -> 11.013938 | J29: =IFERROR(G29/Inputs!$D$13,0) -> 37.88717 | K29: =IFERROR(G29/Inputs!$H$14,0) -> 4986.5605 | L29: =IFERROR(G29/$G$126,0) -> 0.018561548
C30: Total Hard Costs | E30: =IFERROR(0,0) -> 0 | G30: =IFERROR(+SUM(G23:G29),0) -> 44063340 | H30: =IFERROR(G30/Inputs!$D$16,0) -> 3244.1259 | I30: =IFERROR(G30/Inputs!$D$17,0) -> 434.48115 | J30: =IFERROR(G30/Inputs!$D$13,0) -> 1494.5845 | K30: =IFERROR(G30/Inputs!$H$14,0) -> 196711.34 | L30: =IFERROR(G30/$G$126,0) -> 0.73222152
C32: Soft Costs
C33: Environmental - Phase I Report | E33: =IFERROR(0,0) -> 0 | G33: =IFERROR(2500,0) -> 2500 | H33: =IFERROR(G33/Inputs!$D$16,0) -> 0.18406037 | I33: =IFERROR(G33/Inputs!$D$17,0) -> 0.024650943 | J33: =IFERROR(G33/Inputs!$D$13,0) -> 0.084797504 | K33: =IFERROR(G33/Inputs!$H$14,0) -> 11.160714 | L33: =IFERROR(G33/$G$126,0) -> 4.1543691e-05
C34: Environmental - Phase II Report | E34: =IFERROR(0,0) -> 0 | G34: =IFERROR(0,0) -> 0 | H34: =IFERROR(G34/Inputs!$D$16,0) -> 0 | I34: =IFERROR(G34/Inputs!$D$17,0) -> 0 | J34: =IFERROR(G34/Inputs!$D$13,0) -> 0 | K34: =IFERROR(G34/Inputs!$H$14,0) -> 0 | L34: =IFERROR(G34/$G$126,0) -> 0
C35: Geotech-Soils - Soils Investigation | E35: =IFERROR(0,0) -> 0 | G35: =IFERROR(6000,0) -> 6000 | H35: =IFERROR(G35/Inputs!$D$16,0) -> 0.44174489 | I35: =IFERROR(G35/Inputs!$D$17,0) -> 0.059162262 | J35: =IFERROR(G35/Inputs!$D$13,0) -> 0.20351401 | K35: =IFERROR(G35/Inputs!$H$14,0) -> 26.785714 | L35: =IFERROR(G35/$G$126,0) -> 9.970486e-05
C36: ALTA Survey | E36: =IFERROR(0,0) -> 0 | G36: =IFERROR(4000,0) -> 4000 | H36: =IFERROR(G36/Inputs!$D$16,0) -> 0.29449659 | I36: =IFERROR(G36/Inputs!$D$17,0) -> 0.039441508 | J36: =IFERROR(G36/Inputs!$D$13,0) -> 0.13567601 | K36: =IFERROR(G36/Inputs!$H$14,0) -> 17.857143 | L36: =IFERROR(G36/$G$126,0) -> 6.6469906e-05
C37: Soil Management Plan | E37: =IFERROR(0,0) -> 0 | G37: =IFERROR(0,0) -> 0 | H37: =IFERROR(G37/Inputs!$D$16,0) -> 0 | I37: =IFERROR(G37/Inputs!$D$17,0) -> 0 | J37: =IFERROR(G37/Inputs!$D$13,0) -> 0 | K37: =IFERROR(G37/Inputs!$H$14,0) -> 0 | L37: =IFERROR(G37/$G$126,0) -> 0
C38: Architectural - Pre-Conceptual/Massing | E38: =IFERROR(0,0) -> 0 | G38: =IFERROR(0,0) -> 0 | H38: =IFERROR(G38/Inputs!$D$16,0) -> 0 | I38: =IFERROR(G38/Inputs!$D$17,0) -> 0 | J38: =IFERROR(G38/Inputs!$D$13,0) -> 0 | K38: =IFERROR(G38/Inputs!$H$14,0) -> 0 | L38: =IFERROR(G38/$G$126,0) -> 0
C39: Construction Estimating/ROM | E39: =IFERROR(0,0) -> 0 | G39: =IFERROR(0,0) -> 0 | H39: =IFERROR(G39/Inputs!$D$16,0) -> 0 | I39: =IFERROR(G39/Inputs!$D$17,0) -> 0 | J39: =IFERROR(G39/Inputs!$D$13,0) -> 0 | K39: =IFERROR(G39/Inputs!$H$14,0) -> 0 | L39: =IFERROR(G39/$G$126,0) -> 0
C40: Dry/Wet Utility Study | E40: =IFERROR(0,0) -> 0 | G40: =IFERROR(2500,0) -> 2500 | H40: =IFERROR(G40/Inputs!$D$16,0) -> 0.18406037 | I40: =IFERROR(G40/Inputs!$D$17,0) -> 0.024650943 | J40: =IFERROR(G40/Inputs!$D$13,0) -> 0.084797504 | K40: =IFERROR(G40/Inputs!$H$14,0) -> 11.160714 | L40: =IFERROR(G40/$G$126,0) -> 4.1543691e-05
C41: Fee Study | E41: =IFERROR(0,0) -> 0 | G41: =IFERROR(0,0) -> 0 | H41: =IFERROR(G41/Inputs!$D$16,0) -> 0 | I41: =IFERROR(G41/Inputs!$D$17,0) -> 0 | J41: =IFERROR(G41/Inputs!$D$13,0) -> 0 | K41: =IFERROR(G41/Inputs!$H$14,0) -> 0 | L41: =IFERROR(G41/$G$126,0) -> 0
C42: Entitlement Consultant - Land Use Report | E42: =IFERROR(0,0) -> 0 | G42: =IFERROR(0,0) -> 0 | H42: =IFERROR(G42/Inputs!$D$16,0) -> 0 | I42: =IFERROR(G42/Inputs!$D$17,0) -> 0 | J42: =IFERROR(G42/Inputs!$D$13,0) -> 0 | K42: =IFERROR(G42/Inputs!$H$14,0) -> 0 | L42: =IFERROR(G42/$G$126,0) -> 0
C43: Historical | E43: =IFERROR(0,0) -> 0 | G43: =IFERROR(0,0) -> 0 | H43: =IFERROR(G43/Inputs!$D$16,0) -> 0 | I43: =IFERROR(G43/Inputs!$D$17,0) -> 0 | J43: =IFERROR(G43/Inputs!$D$13,0) -> 0 | K43: =IFERROR(G43/Inputs!$H$14,0) -> 0 | L43: =IFERROR(G43/$G$126,0) -> 0
C44: Appraisal | E44: =IFERROR(0,0) -> 0 | G44: =IFERROR(0,0) -> 0 | H44: =IFERROR(G44/Inputs!$D$16,0) -> 0 | I44: =IFERROR(G44/Inputs!$D$17,0) -> 0 | J44: =IFERROR(G44/Inputs!$D$13,0) -> 0 | K44: =IFERROR(G44/Inputs!$H$14,0) -> 0 | L44: =IFERROR(G44/$G$126,0) -> 0
C45: Lead & Asbestos - Report | E45: =IFERROR(0,0) -> 0 | G45: =IFERROR(0,0) -> 0 | H45: =IFERROR(G45/Inputs!$D$16,0) -> 0 | I45: =IFERROR(G45/Inputs!$D$17,0) -> 0 | J45: =IFERROR(G45/Inputs!$D$13,0) -> 0 | K45: =IFERROR(G45/Inputs!$H$14,0) -> 0 | L45: =IFERROR(G45/$G$126,0) -> 0
...

Sheet (Z+) OpEx
C3: Operating Expenses
C5: Operating Expenses & Reserves
C7: Non-Control. Expenses | D7: Factor | E7: Month | F7: Year | G7: PUPM | H7: PUPY | I7: Growth (LU) | J7: Growth (Stab)
C8: Prop. Taxes | D8: =IFERROR(IF(M19=1,1.2%,0),0) -> 0 | E8: =IFERROR(F8/12,0) -> 0 | F8: =IFERROR(+MIN(D8*'(Z+) Dev Budget'!G119,6*'(Z+) Rent Roll'!P20), 0) -> 0 | G8: =IFERROR(+E8/Inputs!$H$14,0) -> 0 | H8: =IFERROR(+F8/Inputs!$H$14,0) -> 0 | I8: =IFERROR(0/100,0) -> 0 | J8: =IFERROR(2/100,0) -> 0.02
C9: Insurance | D9: =IFERROR(69,0) -> 69 | E9: =IFERROR((D9*'(Z+) Rent Roll'!E20)*(1+I9),0) -> 15765.12 | F9: =IFERROR(+E9*12,0) -> 189181.44 | G9: =IFERROR(+E9/Inputs!$H$14,0) -> 70.38 | H9: =IFERROR(+F9/Inputs!$H$14,0) -> 844.56 | I9: =IFERROR(2/100,0) -> 0.02 | J9: =IFERROR(3/100,0) -> 0.03
C10: Management | D10: =IFERROR(5/100,0) -> 0.05 | E10: =IFERROR(('(Z+) Rent Roll'!L20+'(Z+) Rent Roll'!H24)*D10,0) -> 25636.8 | F10: =IFERROR(E10*12,0) -> 307641.6 | G10: =IFERROR(+E10/Inputs!$H$14,0) -> 114.45 | H10: =IFERROR(+F10/Inputs!$H$14,0) -> 1373.4 | I10: =IFERROR(0/100,0) -> 0 | J10: =IFERROR('(Z+) Rent Roll'!M20,0) -> 0.025
C11: CMFA - Fee | D11: =IFERROR(0,0) -> 0 | E11: =IFERROR(F11/12,0) -> 583.33333 | F11: =IFERROR(7000,0) -> 7000 | G11: =IFERROR(+E11/Inputs!$H$14,0) -> 2.6041667 | H11: =IFERROR(F11/Inputs!$H$14,0) -> 31.25 | I11: =IFERROR(0/100,0) -> 0 | J11: =IFERROR(0/100,0) -> 0
C12: Non-Profit Partner - Fee | D12: =IFERROR(0,0) -> 0 | E12: =IFERROR(F12/12,0) -> 4806.6667 | F12: =IFERROR((MAX(20000,250*'(Z+) Rent Roll'!E20))*(1+I12),0) -> 57680 | G12: =IFERROR(+E12/Inputs!$H$14,0) -> 21.458333 | H12: =IFERROR(F12/Inputs!$H$14,0) -> 257.5 | I12: =IFERROR(3/100,0) -> 0.03 | J12: =IFERROR(3/100,0) -> 0.03
C13: Controllable Expenses
C14: Electric | D14: =IFERROR(30,0) -> 30 | E14: =IFERROR((D14*Inputs!$H$14)*(1+I14),0) -> 6921.6 | F14: =IFERROR(E14*12,0) -> 83059.2 | G14: =IFERROR(+E14/Inputs!$H$14,0) -> 30.9 | H14: =IFERROR(+F14/Inputs!$H$14,0) -> 370.8 | I14: =IFERROR(3/100,0) -> 0.03 | J14: =IFERROR(3/100,0) -> 0.03
C15: Water/Sewer | D15: =IFERROR(30,0) -> 30 | E15: =IFERROR((D15*Inputs!$H$14)*(1+I15),0) -> 6921.6 | F15: =IFERROR(E15*12,0) -> 83059.2 | G15: =IFERROR(+E15/Inputs!$H$14,0) -> 30.9 | H15: =IFERROR(+F15/Inputs!$H$14,0) -> 370.8 | I15: =IFERROR(3/100,0) -> 0.03 | J15: =IFERROR(3/100,0) -> 0.03
C16: Gas | D16: =IFERROR(20,0) -> 20 | E16: =IFERROR((D16*Inputs!$H$14)*(1+I16),0) -> 4614.4 | F16: =IFERROR(E16*12,0) -> 55372.8 | G16: =IFERROR(+E16/Inputs!$H$14,0) -> 20.6 | H16: =IFERROR(+F16/Inputs!$H$14,0) -> 247.2 | I16: =IFERROR(3/100,0) -> 0.03 | J16: =IFERROR(3/100,0) -> 0.03
C17: Trash | D17: =IFERROR(28,0) -> 28 | E17: =IFERROR((D17*Inputs!$H$14)*(1+I17),0) -> 6460.16 | F17: =IFERROR(E17*12,0) -> 77521.92 | G17: =IFERROR(+E17/Inputs!$H$14,0) -> 28.84 | H17: =IFERROR(+F17/Inputs!$H$14,0) -> 346.08 | I17: =IFERROR(3/100,0) -> 0.03 | J17: =IFERROR(3/100,0) -> 0.03
C18: Landscape | D18: =IFERROR(0,0) -> 0 | E18: =IFERROR((600*(1+I18)),0) -> 618 | F18: =IFERROR(E18*12,0) -> 7416 | G18: =IFERROR(+E18/Inputs!$H$14,0) -> 2.7589286 | H18: =IFERROR(+F18/Inputs!$H$14,0) -> 33.107143 | I18: =IFERROR(3/100,0) -> 0.03 | J18: =IFERROR(3/100,0) -> 0.03
C19: M&R/Turnover | D19: =IFERROR(50,0) -> 50 | E19: =IFERROR((D19*Inputs!H14)*(1+I19),0) -> 11536 | F19: =IFERROR(E19*12,0) -> 138432 | G19: =IFERROR(+E19/Inputs!$H$14,0) -> 51.5 | H19: =IFERROR(+F19/Inputs!$H$14,0) -> 618 | I19: =IFERROR(3/100,0) -> 0.03 | J19: =IFERROR(3/100,0) -> 0.03 | M19: 1
C20: Payroll/Security | D20: =IFERROR(0,0) -> 0 | E20: =IFERROR(+F20/12,0) -> 29125.973 | F20: =IFERROR((1472*Inputs!H14)*(1+I20),0) -> 349511.68 | G20: =IFERROR(+E20/Inputs!$H$14,0) -> 130.02667 | H20: =IFERROR(+F20/Inputs!$H$14,0) -> 1560.32 | I20: =IFERROR(6/100,0) -> 0.06 | J20: =IFERROR(3/100,0) -> 0.03
C21: HCID Fee | D21: =IFERROR(22,0) -> 22 | E21: =(D21*Inputs!H14)*(1+I21) -> 5075.84 | F21: =IFERROR(E21*12,0) -> 60910.08 | G21: =IFERROR(+E21/Inputs!$H$14,0) -> 22.66 | H21: =IFERROR(+F21/Inputs!$H$14,0) -> 271.92 | I21: =IFERROR(3/100,0) -> 0.03 | J21: =IFERROR(3/100,0) -> 0.03
C22: Elevator Maint. | D22: =IFERROR(5,0) -> 5 | E22: =IFERROR(1000*(1+I22),0) -> 1030 | F22: =IFERROR(E22*12,0) -> 12360 | G22: =IFERROR(+E22/Inputs!$H$14,0) -> 4.5982143 | H22: =IFERROR(+F22/Inputs!$H$14,0) -> 55.178571 | I22: =IFERROR(3/100,0) -> 0.03 | J22: =IFERROR(3/100,0) -> 0.03
C23: Legal | D23: =IFERROR(5,0) -> 5 | E23: =IFERROR((D23*Inputs!H14)*(1+I23),0) -> 1153.6 | F23: =IFERROR(E23*12,0) -> 13843.2 | G23: =IFERROR(+E23/Inputs!$H$14,0) -> 5.15 | H23: =IFERROR(+F23/Inputs!$H$14,0) -> 61.8 | I23: =IFERROR(3/100,0) -> 0.03 | J23: =IFERROR(3/100,0) -> 0.03
C24: Misc. | D24: =IFERROR(180,0) -> 180 | E24: =IFERROR((D24*Inputs!H14)*(1+I24),0) -> 41529.6 | F24: =IFERROR(E24*12,0) -> 498355.2 | G24: =IFERROR(+E24/Inputs!$H$14,0) -> 185.4 | H24: =IFERROR(+F24/Inputs!$H$14,0) -> 2224.8 | I24: =IFERROR(3/100,0) -> 0.03 | J24: =IFERROR(3.1/100,0) -> 0.031
C25: Mgr's Rent Credit | D25: =IFERROR(0,0) -> 0 | E25: =IFERROR((D25*Inputs!H14)*(1+I25),0) -> 0 | F25: =IFERROR(E25*12,0) -> 0 | G25: =IFERROR(+E25/Inputs!$H$14,0) -> 0 | H25: =IFERROR(+F25/Inputs!$H$14,0) -> 0 | I25: =IFERROR(3/100,0) -> 0.03 | J25: =IFERROR(3.1/100,0) -> 0.031
C26: Reserves | D26: =IFERROR(1,0) -> 1 | E26: =IFERROR((D26*Inputs!H14)*(1+I26),0) -> 230.72 | F26: =IFERROR(E26*12,0) -> 2768.64 | G26: =IFERROR(+E26/Inputs!$H$14,0) -> 1.03 | H26: =IFERROR(+F26/Inputs!H14,0) -> 12.36 | I26: =IFERROR(3/100,0) -> 0.03 | J26: =IFERROR(3/100,0) -> 0.03
C27: Total | D27: =IFERROR(F27/G35, 0) -> 0.31681548 | E27: =IFERROR(SUM(E8:E26),0) -> 162009.41 | F27: =IFERROR(SUM(F8:F26),0) -> 1944113 | G27: =IFERROR(SUM(G8:G26),0) -> 723.25631 | H27: =IFERROR(SUM(H8:H26),0) -> 8679.0757 | I27: =IFERROR(3/100,0) -> 0.03 | J27: =IFERROR(SUMPRODUCT(J8:J26,H8:H26)/SUM(H8:H26), 0) -> 0.029357109
F29: Untrended (Today) | I29: Trended (Stabilization)
C30: Operating Summary | F30: Covenants | G30: As Rented | H30: Tax Exempt | I30: Covenants | J30: As Rented | K30: Tax Exempt
C31: Residential Rents (GPR) | F31: =IFERROR('(Z+) Rent Roll'!H20*12*Inputs!$H$14,0) -> 6152832 | G31: =IFERROR('(Z+) Rent Roll'!L20*12,0) -> 6152832 | H31: =IFERROR(+G31,0) -> 6152832 | I31: =IFERROR('(Z+) Rent Roll'!H20*12*Inputs!$F$34,0) -> 29337.562 | J31: =IFERROR(INDEX('(Z+) Monthly CF'!$F$14:$HB$14,1,MATCH(Inputs!$D$34,'(Z+) Monthly CF'!$F$5:$HB$5,0))*12,0) -> 6571613.8 | K31: =IFERROR(+J31,0) -> 6571613.8
C32: Commercial Rents (MG, net of Vac) | F32: =IFERROR('(Z+) Rent Roll'!$H$24*12,0) -> 0 | G32: =IFERROR('(Z+) Rent Roll'!$H$24*12,0) -> 0 | H32: =IFERROR('(Z+) Rent Roll'!$H$24*12,0) -> 0 | I32: =IFERROR('(Z+) Rent Roll'!$H$24*12*Inputs!$F$34,0) -> 0 | J32: =IFERROR('(Z+) Rent Roll'!$H$24*12,0) -> 0 | K32: =IFERROR('(Z+) Rent Roll'!$H$24*12,0) -> 0
C33: Other Income | F33: =IFERROR('(Z+) Rent Roll'!$H$36*12,0) -> 168173.38 | G33: =IFERROR('(Z+) Rent Roll'!$H$36*12,0) -> 168173.38 | H33: =IFERROR('(Z+) Rent Roll'!$H$36*12,0) -> 168173.38 | I33: =IFERROR('(Z+) Rent Roll'!$H$36*12*Inputs!$F$34,0) -> 179619.8 | J33: =IFERROR(INDEX('(Z+) Monthly CF'!$F$15:$HB$15,1,MATCH(Inputs!$D$34,'(Z+) Monthly CF'!$F$5:$HB$5,0))*12,0) -> 179619.8 | K33: =IFERROR(+J33,0) -> 179619.8
C34: Residential Losses | F34: =IFERROR(-'(Z+) Rent Roll'!N20*F31,0) -> -184584.96 | G34: =IFERROR(-'(Z+) Rent Roll'!N20*G31,0) -> -184584.96 | H34: =IFERROR(+G34,0) -> -184584.96 | I34: =IFERROR(-'(Z+) Rent Roll'!N20*I31,0) -> -880.12685 | J34: =IFERROR(INDEX('(Z+) Monthly CF'!$F$17:$HB$17,1,MATCH(Inputs!$D$34,'(Z+) Monthly CF'!$F$5:$HB$5,0))*12,0) -> -197148.41 | K34: =IFERROR(+J34,0) -> -197148.41
C35: Effective Gross Income | F35: =IFERROR(SUM(F31:F34),0) -> 6136420.4 | G35: =IFERROR(SUM(G31:G34),0) -> 6136420.4 | H35: =IFERROR(SUM(H31:H34),0) -> 6136420.4 | I35: =IFERROR(SUM(I31:I34),0) -> 208077.24 | J35: =IFERROR(SUM(J31:J34),0) -> 6554085.2 | K35: =IFERROR(SUM(K31:K34),0) -> 6554085.2
C36: Operating Expenses | F36: =IFERROR(-SUM(F14:F26,F8,F9)-$D$10*F31,0) -> -1879433 | G36: =IFERROR(-F27,0) -> -1944113 | H36: =IFERROR(+G36+$F$8*(SUM('(Z+) Rent Roll'!E12:E19)/Inputs!H14),0) -> -1944113 | I36: =IFERROR(J36+$D$10*(J31-I31),0) -> -1400844.5 | J36: =IFERROR(INDEX('(Z+) Monthly CF'!$F$47:$HB$47,1,MATCH(Inputs!$D$34,'(Z+) Monthly CF'!$F$5:$HB$5,0))*12,0) -> -1727958.3 | K36: =IFERROR(+J36+F8*(SUM('(Z+) Rent Roll'!E12:E19)/Inputs!H14),0) -> -1727958.3
C37: Net Operating Income | F37: =IFERROR(SUM(F35:F36),0) -> 4256987.5 | G37: =IFERROR(SUM(G35:G36),0) -> 4192307.5 | H37: =IFERROR(SUM(H35:H36),0) -> 4192307.5 | I37: =IFERROR(SUM(I35:I36),0) -> -1192767.3 | J37: =IFERROR(SUM(J35:J36),0) -> 4826126.8 | K37: =IFERROR(SUM(K35:K36),0) -> 4826126.8
C38: Return on Cost | F38: =IFERROR(F37/('(Z+) Dev Budget'!$G$126-'(Z+) Dev Budget'!$G$22),0) -> 0.071248263 | G38: =IFERROR(G37/('(Z+) Dev Budget'!$G$126-'(Z+) Dev Budget'!$G$22),0) -> 0.070165728 | H38: =IFERROR(H37/('(Z+) Dev Budget'!$G$126-'(Z+) Dev Budget'!$G$22),0) -> 0.070165728 | I38: =IFERROR(I37/'(Z+) Dev Budget'!$G$126,0) -> -0.019820783 | J38: =IFERROR(J37/'(Z+) Dev Budget'!$G$126,0) -> 0.080198049 | K38: =IFERROR(+K37/'(Z+) Dev Budget'!$G$126,0) -> 0.080198049
C39: Cash-on-Cash | F39: =IFERROR((F37+IPMT('(Z+) Financing'!$H$18*365.25/360,1,'(Z+) Financing'!$H$21,'(Z+) Financing'!$H$19))/Inputs!$L$23,0) -> 0.12656009 | G39: =IFERROR((G37+IPMT('(Z+) Financing'!$H$18*365.25/360,1,'(Z+) Financing'!$H$21,'(Z+) Financing'!$H$19))/Inputs!$L$23,0) -> 0.12090861 | H39: =IFERROR((H37+IPMT('(Z+) Financing'!$H$18*365.25/360,1,'(Z+) Financing'!$H$21,'(Z+) Financing'!$H$19))/Inputs!$L$23,0) -> 0.12090861 | I39: =IFERROR((I37+IPMT('(Z+) Financing'!$H$18*365.25/360,1,'(Z+) Financing'!$H$21,'(Z+) Financing'!$H$19))/Inputs!$L$23,0) -> -0.34961778 | J39: =IFERROR((J37+IPMT('(Z+) Financing'!$H$18*365.25/360,1,'(Z+) Financing'!$H$21,'(Z+) Financing'!$H$19))/Inputs!$L$23,0) -> 0.17628922 | K39: =IFERROR((K37+IPMT('(Z+) Financing'!$H$18*365.25/360,1,'(Z+) Financing'!$H$21,'(Z+) Financing'!$H$19))/Inputs!$L$23,0) -> 0.17628922
C40: Operating Ratio | F40: =IFERROR(IFERROR(-F36/F35,0),0) -> 0.30627513 | G40: =IFERROR(-G36/G35,0) -> 0.31681548 | H40: =IFERROR(-H36/H35,0) -> 0.31681548 | I40: =IFERROR(-I36/I35,0) -> 6.7323295 | J40: =IFERROR(-J36/J35,0) -> 0.263646 | K40: =IFERROR(-K36/K35,0) -> 0.263646
C41: Valuation | F41: =IFERROR((F37+$F$8)/('(Z+) Financing'!$H$8+$D$8),0) -> 74034564 | G41: =IFERROR((G37+$F$8)/('(Z+) Financing'!$H$8+$D$8),0) -> 72909695 | H41: =IFERROR((H37+$F$8)/('(Z+) Financing'!$H$8+$D$8),0) -> 72909695 | I41: =IFERROR((I37+$F$8*1.02^(Inputs!$E$33/12))/('(Z+) Financing'!$H$8+$D$8),0) -> -20743779 | J41: =IFERROR((J37+$F$8*1.02^(Inputs!$E$33/12))/('(Z+) Financing'!$H$8+$D$8),0) -> 83932640 | K41: =IFERROR((K37+$F$8*1.02^(Inputs!$E$33/12))/('(Z+) Financing'!$H$8+$D$8),0) -> 83932640
C42: Per Unit | F42: =IFERROR(F41/Inputs!H14,0) -> 330511.45 | G42: =IFERROR(G41/Inputs!H14,0) -> 325489.71 | H42: =IFERROR(H41/Inputs!H14,0) -> 325489.71 | I42: =IFERROR(I41/Inputs!H14,0) -> -92606.157 | J42: =IFERROR(J41/Inputs!H14,0) -> 374699.29 | K42: =IFERROR(K41/Inputs!H14,0) -> 374699.29
C43: Value-Add | F43: =IFERROR(F41/'(Z+) Dev Budget'!$G$126-1,0) -> 0.23026764 | G43: =IFERROR(G41/'(Z+) Dev Budget'!$G$126-1,0) -> 0.21157515 | H43: =IFERROR(H41/'(Z+) Dev Budget'!$G$126-1,0) -> 0.21157515 | I43: =IFERROR(I41/'(Z+) Dev Budget'!$G$126-1,0) -> -1.3447093 | J43: =IFERROR(J41/'(Z+) Dev Budget'!$G$126-1,0) -> 0.39474869 | K43: =IFERROR(K41/'(Z+) Dev Budget'!$G$126-1,0) -> 0.39474869

Sheet (Z+) Financing
C3: Financing
C5: Acquisition Financing | F5: Permanent Financing | J5: LP Returns
C6: LTC | D6: =IFERROR(0/100,0) -> 0 | F6: Underwriting Method | H6: As Rented | J6: Project Unlevered IRR | K6: ='(Z+) Monthly CF'!F102 -> 0.097391468
C7: Interest Rate | D7: =IFERROR(8.37/100,0) -> 0.0837 | F7: Underwritten NOI | H7: =+IFERROR('(Z+) OpEx'!J37,0) -> 4826126.8 | J7: Project Levered IRR | K7: =IFERROR('(Z+) Monthly CF'!F103,0) -> 0.15538478
C8: Closing Costs % | D8: =IFERROR(1/100,0) -> 0.01 | F8: Cap Rate | H8: =+IFERROR(5.75/100,0) -> 0.0575 | J8: Going-In Cash/Cash | K8: =+IFERROR('(Z+) OpEx'!G39,0) -> 0.12090861
C9: Closing Costs | D9: =IFERROR(D8*D10,0) -> 0 | F9: Valuation at Refi | H9: =MIN(H7/H8,(INDEX('(Z+) OpEx'!$I$37:$K$37,MATCH(H6,'(Z+) OpEx'!$I$30:$K$30,0))+'(Z+) OpEx'!F8*1.02^(Inputs!E33/12))/(H8+'(Z+) OpEx'!D8)) -> 83932640 | J9: Stabilized Project Cash/Cash | K9: =IFERROR('(Z+) OpEx'!J39,0) -> 0.17628922
C10: Loan Proceeds | D10: =IFERROR(D6*'(Z+) Dev Budget'!G10,0) -> 0 | F10: Value-Add | H10: =+H9/'(Z+) Dev Budget'!G126-1 -> 0.39474869 | J10: Going-In Return on Cost | K10: =+IFERROR('(Z+) OpEx'!G38,0) -> 0.070165728
F11: Minimum DSCR | H11: 1.2 | J11: Stabilized Return on Cost | K11: =IFERROR('(Z+) OpEx'!J38,0) -> 0.080198049
C12: Mezzanine Financing | D12: OFF | F12: DSCR Rate Margin | H12: =0 -> 0 | J12: Equity Multiple (Project-Level) | K12: =IFERROR('(Z+) Monthly CF'!F104,0) -> 1.7201935
C13: Underwriting Method | D13: Covenants | F13: DSCR Loan Amount | H13: =-PV((H18+H12)/12*365.25/360,H21*12,H7/H11/12) -> 59946712 | J13: Gross Profit | K13: =IFERROR('(Z+) Monthly CF'!D73,0) -> 34023171
C14: Underwritten NOI | D14: =+MIN(INDEX('(Z+) OpEx'!$F$37:$H$37,MATCH(D13,'(Z+) OpEx'!$F$30:$H$30,0)),INDEX('(Z+) OpEx'!$F$35:$H$35,MATCH(D28,'(Z+) OpEx'!$F$30:$H$30,0))*(1-'(Z+) OpEx'!D27)) -> 4192307.5 | F14: Max LTV | H14: =75/100 -> 0.75 | J14: Levered Profit | K14: =IFERROR('(Z+) Monthly CF'!D100,0) -> 17170572
C15: Cap Rate | D15: =IFERROR(5.75/100,0) -> 0.0575 | F15: LTV Loan Amount | H15: =H9*H14 -> 62949480
C16: Interest Rate | D16: =IFERROR(11/100,0) -> 0.11 | F16: Max LTC | H16: =80/100 -> 0.8
C17: Valuation at Refi | D17: =MIN(D14/D15,(INDEX('(Z+) OpEx'!$F$37:$H$37,MATCH(D13,'(Z+) OpEx'!$F$30:$H$30,0))+'(Z+) OpEx'!F8)/(D30+'(Z+) OpEx'!D8)) -> 70949791 | F17: LTC Loan Amount | H17: =IFERROR('(Z+) Dev Budget'!G126*H16,0) -> 48142087
C18: Max LTC | D18: =IFERROR(70/100,0) -> 0.7 | F18: Interest Rate | H18: =Dashboard!K12 -> 0.0575
C19: LTC Loan Amount | D19: =IFERROR((D18-D32)*'(Z+) Dev Budget'!G118,0) -> 0 | F19: Loan Proceeds | H19: =ROUNDDOWN(MIN(H13,H15,H17),-3) -> 48142000
C20: Debt Yield | D20: =IFERROR(6.5/100,0) -> 0.065 | F20: Net After Fees | H20: =+H19*(1-H22) -> 47660580
C21: DY Loan Amount | D21: =(D14/D20)-D38 -> 28161038 | F21: Amortization | H21: 35
C22: Loan Proceeds | D22: =MAX(0,ROUNDDOWN(MIN(D19,D21),-3))*($D$12="ON") -> 0 | F22: Fees | H22: =IFERROR(1/100,0) -> 0.01
C23: Closing Costs % | D23: =IFERROR(1.5/100,0) -> 0.015 | F23: LTV | H23: =IFERROR(H19/(H7/H8),0) -> 0.573579
C24: Closing Costs | D24: =D22*D23*1.005 -> 0 | F24: LTC | H24: =IFERROR(H19/'(Z+) Dev Budget'!G126,0) -> 0.79999856
C25: LTC | D25: =IFERROR(+D22/'(Z+) Dev Budget'!G126,0) -> 0
F26: Exit Valuation | G26: Covenants | H26: As Rented
C27: Construction Financing | F27: Exit Month | G27: =IFERROR(Inputs!E38,0) -> 49034 | H27: =IFERROR(Inputs!E38,0) -> 49034
C28: Underwriting Method | D28: As Rented | F28: Cap Rate (Exit) | G28: =IFERROR(5.75/100,0) -> 0.0575 | H28: =IFERROR(Dashboard!J5,0) -> 0.0675
C29: Underwritten NOI | D29: =+MIN(INDEX('(Z+) OpEx'!$I$37:$K$37,MATCH(D28,'(Z+) OpEx'!$I$30:$K$30,0)),INDEX('(Z+) OpEx'!$I$35:$K$35,MATCH(D28,'(Z+) OpEx'!$I$30:$K$30,0))*(1-'(Z+) OpEx'!D27)) -> 4477649.6 | F29: Fwd EGI at Exit | G29: =IFERROR(SUMIF('(Z+) Monthly CF'!$4:$4,"<="&EOMONTH(Inputs!E$38,12),'(Z+) Monthly CF'!$29:$29)-SUMIF('(Z+) Monthly CF'!$4:$4,"<="&Inputs!E$38,'(Z+) Monthly CF'!$29:$29),0) -> 236154.02 | H29: =IFERROR(SUMIF('(Z+) Monthly CF'!$4:$4,"<="&EOMONTH(Inputs!E$38,12),'(Z+) Monthly CF'!$19:$19)-SUMIF('(Z+) Monthly CF'!$4:$4,"<="&Inputs!E$38,'(Z+) Monthly CF'!$19:$19),0) -> 7438456.8
C30: Cap Rate | D30: =+IFERROR(6/100,0) -> 0.06 | F30: Fwd NOI at Exit | G30: =IFERROR('(Z+) OpEx'!F37,0) -> 4256987.5 | H30: =IFERROR('(Z+) OpEx'!G37,0) -> 4192307.5
C31: Valuation at Refi | D31: =MIN(D29/D30,(INDEX('(Z+) OpEx'!$F$37:$H$37,MATCH(D28,'(Z+) OpEx'!$F$30:$H$30,0))+'(Z+) OpEx'!F8)/(D30+'(Z+) OpEx'!D8)) -> 69871791 | F31: Adj NOI at Exit | G31: =IFERROR(G30,0) -> 4256987.5 | H31: =IFERROR(H30,0) -> 4192307.5
C32: Max LTC | D32: =+IFERROR(Dashboard!J11,0) -> 0.7 | F32: Value at Exit | G32: =IFERROR(MIN(G30,G31)/G28,0) -> 74034564 | H32: =IFERROR(MIN(H30,H31)/H28,0) -> 62108259
C33: LTC Loan Amount | D33: =+IFERROR(D32*'(Z+) Dev Budget'!G118,0) -> 36336474 | F33: GSF | G33: =IFERROR(G32/Inputs!D16,0) -> 5450.7318 | H33: =IFERROR(H32/Inputs!D16,0) -> 4572.6677
C34: Max LTV | D34: 0.75 | F34: LSF | G34: =IFERROR(G32/Inputs!D13,0) -> 2511.1785 | H34: =IFERROR(H32/Inputs!D13,0) -> 2106.6501
C35: LTV Loan Amount | D35: =IFERROR(D34*D31,0) -> 52403843 | F35: RSF | G35: =IFERROR(G32/Inputs!D16,0) -> 5450.7318 | H35: =IFERROR(H32/Inputs!D16,0) -> 4572.6677
C36: Interest Rate | D36: =Dashboard!J12 -> 0.09 | F36: Unit | G36: =IFERROR(G32/'(Z+) Rent Roll'!E20,0) -> 330511.45 | H36: =IFERROR(H32/'(Z+) Rent Roll'!E20,0) -> 277269.01
C37: DSCR Loan Amount | D37: =-PV((H18+H12)/12*365.25/360,H21*12,D29/H11/12) -> 55618175 | F37: Appreciation to Cost | G37: =IFERROR((G32-'(Z+) Dev Budget'!G126)/'(Z+) Dev Budget'!G126,0) -> 0.23026764 | H37: =IFERROR((H32-'(Z+) Dev Budget'!G126)/'(Z+) Dev Budget'!G126,0) -> 0.032082534
C38: Loan Proceeds | D38: =+ROUNDDOWN(D33,-3) -> 36336000 | F38: Sale Costs | G38: =IFERROR(2.5%+0.013373,0) -> 0.038373 | H38: =IFERROR(0.025+0.013373,0) -> 0.038373
C39: Closing Costs % | D39: =1/100 -> 0.01 | F39: Sales Proceeds | G39: =IFERROR(G32*(1-G38),0) -> 71193636 | H39: =IFERROR(H32*(1-H38),0) -> 59724978
C40: Closing Costs | D40: =D38*D39*1.005 -> 365176.8 | F40: Sale Proceeds | G40: As Rented | H40: =IFERROR(IF(G40="Covenants",G39,H39),0) -> 59724978
C41: LTC | D41: =IFERROR(+D38/'(Z+) Dev Budget'!G126,0) -> 0.60381263
C43: Subordinate / Soft Debt — Amount | D43: 0
C44: Sub Rate | D44: 0
...

Sheet (Z+) Rent Roll
C3: Rent Roll
C5: Rent Roll - Residential
C6: Unit Type | D6: Beds | E6: Units | F6: Utility Allowance | G6: Natural Rent | H6: Nat. Income | I6: Voucher Pmt | J6: % Subsid. | K6: Adj. Rents | L6: Adj. Income | M6: Growth | N6: Stab. Vac. | O6: Avg SF | P6: NRSF | Q6: PSF Rent | R6: OS/Unit | S6: Tot. OS
C7: Manager 1BR | E7: =IFERROR(1,0) -> 1 | F7: =IFERROR(0,0) -> 0 | G7: =IFERROR(I7-F7,0) -> 2289 | H7: =IFERROR(G7*E7,0) -> 2289 | I7: =IFERROR(I9,0) -> 2289 | J7: =IFERROR(100/100,0) -> 1 | K7: =IFERROR((I7-G7)*J7+G7,0) -> 2289 | L7: =IFERROR(K7*E7,0) -> 2289 | M7: =IFERROR(+Inputs!$L$7,0) -> 0.025 | N7: =IFERROR(+Inputs!$L$6,0) -> 0.03 | O7: =IFERROR(O13,0) -> 419 | P7: =IFERROR(O7*E7,0) -> 419 | Q7: =IFERROR(K7/O7,0) -> 5.4630072 | R7: =IFERROR(100,0) -> 100 | S7: =IFERROR(R7*E7,0) -> 100
C8: Market Rate 0BR | D8: =IFERROR(1,0) -> 1 | E8: =IFERROR(IF(Inputs!$O$29="NO",ROUND((Inputs!$H$14-$E$7-Inputs!$O$32)*M24,0),0),0) -> 0 | F8: =IFERROR(0,0) -> 0 | G8: =IFERROR(2041-F8,0) -> 2041 | H8: =IFERROR(G8*E8,0) -> 0 | I8: =IFERROR(G8,0) -> 2041 | J8: =IFERROR(100/100,0) -> 1 | K8: =IFERROR((I8-G8)*J8+G8,0) -> 2041 | L8: =IFERROR(K8*E8,0) -> 0 | M8: =IFERROR(+Inputs!$L$7,0) -> 0.025 | N8: =IFERROR(+Inputs!$L$6,0) -> 0.03 | O8: =IFERROR(310,0) -> 310 | P8: =IFERROR(O8*E8,0) -> 0 | Q8: =IFERROR(K8/O8,0) -> 6.583871 | R8: =IFERROR(100,0) -> 100 | S8: =IFERROR(R8*E8,0) -> 0
C9: Market Rate 1BR | D9: =IFERROR(0,0) -> 0 | E9: =IFERROR(IF(Inputs!$O$29="NO",ROUND((Inputs!$H$14-$E$7-Inputs!$O$32)*M25,0),0),0) -> 0 | F9: =IFERROR(0,0) -> 0 | G9: =IFERROR(2289-F9,0) -> 2289 | H9: =IFERROR(G9*E9,0) -> 0 | I9: =IFERROR(G9,0) -> 2289 | J9: =IFERROR(100/100,0) -> 1 | K9: =IFERROR((I9-G9)*J9+G9,0) -> 2289 | L9: =IFERROR(K9*E9,0) -> 0 | M9: =IFERROR(+Inputs!$L$7,0) -> 0.025 | N9: =IFERROR(+Inputs!$L$6,0) -> 0.03 | O9: =IFERROR(419,0) -> 419 | P9: =IFERROR(O9*E9,0) -> 0 | Q9: =IFERROR(K9/O9,0) -> 5.4630072 | R9: =IFERROR(100,0) -> 100 | S9: =IFERROR(R9*E9,0) -> 0
C10: Market Rate 2BR | D10: =IFERROR(2,0) -> 2 | E10: =IFERROR(IF(Inputs!$O$29="NO",ROUND((Inputs!$H$14-$E$7-Inputs!$O$32)*M26,0),0),0) -> 0 | F10: =IFERROR(0,0) -> 0 | G10: =IFERROR(2887-F10,0) -> 2887 | H10: =IFERROR(G10*E10,0) -> 0 | I10: =IFERROR(G10,0) -> 2887 | J10: =IFERROR(100/100,0) -> 1 | K10: =IFERROR((I10-G10)*J10+G10,0) -> 2887 | L10: =IFERROR(K10*E10,0) -> 0 | M10: =IFERROR(+Inputs!$L$7,0) -> 0.025 | N10: =IFERROR(+Inputs!$L$6,0) -> 0.03 | O10: =IFERROR(730,0) -> 730 | P10: =IFERROR(O10*E10,0) -> 0 | Q10: =IFERROR(K10/O10,0) -> 3.9547945 | R10: =IFERROR(100,0) -> 100 | S10: =IFERROR(R10*E10,0) -> 0
C11: Market Rate 3BR | D11: =IFERROR(3,0) -> 3 | E11: =IFERROR(IF(Inputs!$O$29="NO",ROUND((Inputs!$H$14-$E$7-Inputs!$O$32)*M27,0),0),0) -> 0 | F11: =IFERROR(0,0) -> 0 | G11: =IFERROR(3668-F11,0) -> 3668 | H11: =IFERROR(G11*E11,0) -> 0 | I11: =IFERROR(G11,0) -> 3668 | J11: =IFERROR(100/100,0) -> 1 | K11: =IFERROR((I11-G11)*J11+G11,0) -> 3668 | L11: =IFERROR(K11*E11,0) -> 0 | M11: =IFERROR(+Inputs!$L$7,0) -> 0.025 | N11: =IFERROR(+Inputs!$L$6,0) -> 0.03 | O11: =IFERROR(830,0) -> 830 | P11: =IFERROR(O11*E11,0) -> 0 | Q11: =IFERROR(K11/O11,0) -> 4.4192771 | R11: =IFERROR(100,0) -> 100 | S11: =IFERROR(R11*E11,0) -> 0
C12: HUD/TCAC 80% AMI 0BR | D12: =IFERROR(1,0) -> 1 | E12: =IFERROR(ROUND((Inputs!H14-$E$7-SUM($E$16:$E$19)-SUM($E$8:$E$11))*M24,0),0) -> 0 | F12: =IFERROR(0,0) -> 0 | G12: =IFERROR(0,0) -> 0 | H12: =IFERROR(G12*E12,0) -> 0 | I12: =IFERROR(2023.68,0) -> 2023.68 | J12: =IFERROR(100/100,0) -> 1 | K12: =IFERROR((I12-G12)*J12+G12,0) -> 2023.68 | L12: =IFERROR(K12*E12,0) -> 0 | M12: =IFERROR(+Inputs!$L$7,0) -> 0.025 | N12: =IFERROR(+Inputs!$L$6,0) -> 0.03 | O12: =IFERROR(O8,0) -> 310 | P12: =IFERROR(O12*E12,0) -> 0 | Q12: =IFERROR(K12/O12,0) -> 6.528 | R12: =IFERROR(100,0) -> 100 | S12: =IFERROR(R12*E12,0) -> 0
